Workbook

Sheet Organismo
E1: Tipo de Nómina | F1: Periodicidad de Pago | G1: Fecha de Pago | H1: Fecha Inicial de pago | I1: Fecha Final de pago | J1: Clave Periodicidad de Pago | K1: Clave Tipo de Nómina | L1: Numero de días pagados | M1: Nómina Sindicalizada
B2: Versión | C2: 3.3 | E2: Nómina Ordinaria | F2: Mensual | G2: 44330 | H2: 44317 | I2: 44347 | J2: =IF(TablaOrganismo[Periodicidad de Pago]="","",VLOOKUP(TablaOrganismo[Periodicidad de Pago],Cat!$D$1:$E$12,2,0)) -> 5 | K2: =IF(TablaOrganismo[Tipo de Nómina]="","",VLOOKUP(TablaOrganismo[Tipo de Nómina],Cat!$A$2:$B$3,2,0)) -> O | L2: =IF(OR(TablaOrganismo[Fecha Inicial de pago]>TablaOrganismo[Fecha Final de pago],TablaOrganismo[Fecha Inicial de pago]="",TablaOrganismo[Fecha Final de pago]=""),"",TablaOrganismo[Fecha Final de pago]-TablaOrganismo[Fecha Inicial de pago]+1) -> 31 | M2: No
B3: Serie | C3: =CONCATENATE(COUNT(TablaTrabajadores[[#All],[Número de Empleado]]),IF(TablaOrganismo[Nómina Sindicalizada]="No","C","S"),IFERROR(IF(FIND(" ",E4)>0,LEFT(E4,1)&MID(E4,FIND(" ",E4)+1,1)),LEFT(E4,1)),TEXT(TablaOrganismo[Fecha de Pago],"aaaa"),TEXT(TablaOrganismo[Fecha de Pago],"mmm"),IF(TEXT(TablaOrganismo[Fecha de Pago],"dd")="15","1era","2da"),TablaOrganismo[Clave Tipo de Nómina]) -> 18CO2021may2daO
B4: Forma de Pago | C4: 99 | E4: O
B5: Método de Pago | C5: N
B6: Tipo de Comprobante | C6: PUE
B7: Moneda | C7: MXN
B8: Código Postal | C8: 29039
B9: RFC del Organismo | C9: SCR0103101R0
B10: Nombre del Organismo | C10: SISTEMA CHIAPANECO DE RADIO, TELEVISIÓN Y CINEMATOGRAFÍA
B11: Régimen Fiscal del Organismo | C11: 603
B12: Registro Patronal del Organismo | C12: A6831083386
B13: Régimen Fiscal del Organismo | C13: Personas Morales con Fines no Lucrativos

Sheet Trabajadores
A1: Consecutivo Trabajador | B1: RFC Trabajador | C1: Nombre Trabajador | D1: CURP | E1: NSS | F1: Fecha Inicio Relación Laboral | G1: Tipo de Contrato | H1: Tipo de Régimen | I1: Número de Empleado | J1: Departamento | K1: Puesto | L1: Riesgo de Puesto | M1: Salario Diario Integrado | N1: Origen del Recurso | O1: Monto Recurso Propio | P1: Entidad Federativa | Q1: Correo Electrónico | R1: CC | S1: CCO | T1: Clave Tipo de Contrato | U1: Clave Tipo de Régimen | V1: Total de Percepciones | W1: Total de Deducciones | X1: Total de Otros Pagos | Y1: Antigüedad | Z1: ConteoPercepciones | AA1: ConteoDeducciones | AB1: Total Gravado | AC1: Total Exento | AD1: Total Otras Deducciones | AE1: Total Impuestos Retenidos | AF1: ClaveOrigen del Recurso2 | AG1: ClaveEntidadFederativa | AH1: ConteoHorasExtra | AI1: ConteOtrosPagos | AJ1: ClaveJornada | AK1: TotalSueldos | AL1: TotalSeparacionIndemnizacion | AM1: TotalJubilacionPensionRetiro | AN1: Tipo de Jornada
A2: 1 | B2: CAOA900910AZ9 | C2: CAMACHO OVANDO ALAN ULISES | D2: CAOA900910HCSMVL04 | E2: 71089008313 | F2: 42826 | G2: Contrato de trabajo por tiempo indeterminado | H2: Sueldos | I2: 967 | J2: AREA DE RECURSOS MATERIALES | K2: VELADOR | L2: 1 | M2: 157.26603 | N2: Ingresos propios | P2: Chiapas | Q2: camacho.ovando@hotmail.com | R2: canal10humanos@gmail.com | T2: =IF(TablaTrabajadores[[#This Row],[Tipo de Contrato]]="","",VLOOKUP(TablaTrabajadores[[#This Row],[Tipo de Contrato]],Cat!$G$1:$H$12,2,0)) -> 1 | U2: =IF(TablaTrabajadores[[#This Row],[Tipo de Régimen]]="","",VLOOKUP(TablaTrabajadores[[#This Row],[Tipo de Régimen]],Cat!$J$1:$K$13,2,0)) -> 2 | V2: =ROUND(IF((SUMIF(TablaPercepciones[[#All],[Trabajador]],TablaTrabajadores[[#This Row],[Nombre Trabajador]],TablaPercepciones[[#All],[Importe Gravado]])+SUMIF(TablaPercepciones[[#All],[Trabajador]],TablaTrabajadores[[#This Row],[Nombre Trabajador]],TablaPercepciones[[#All],[o]]))=0,0,SUMIF(TablaPercepciones[[#All],[Trabajador]],TablaTrabajadores[[#This Row],[Nombre Trabajador]],TablaPercepciones[[#All],[Importe Gravado]])+SUMIF(TablaPercepciones[[#All],[Trabajador]],TablaTrabajadores[[#This Row],[Nombre Trabajador]],TablaPercepciones[[#All],[o]])),2) -> #REF! | W2: =ROUND(IF((SUMIF(TablaDeducciones[[#All],[Trabajador]],TablaTrabajadores[[#This Row],[Nombre Trabajador]],TablaDeducciones[[#All],[Importe]]))=0,0,SUMIF(TablaDeducciones[[#All],[Trabajador]],TablaTrabajadores[[#This Row],[Nombre Trabajador]],TablaDeducciones[[#All],[Importe]])),2) -> #REF! | X2: =ROUND(IF((SUMIF(TablaOtrosPagos[[#All],[Trabajador]],TablaTrabajadores[[#This Row],[Nombre Trabajador]],TablaOtrosPagos[[#All],[Importe]]))=0,0,SUMIF(TablaOtrosPagos[[#All],[Trabajador]],TablaTrabajadores[[#This Row],[Nombre Trabajador]],TablaOtrosPagos[[#All],[Importe]])),2) -> #REF! | Y2: =IF(OR(TablaOrganismo[Fecha Final de pago]="",TablaTrabajadores[[#This Row],[Fecha Inicio Relación Laboral]]=""),"",CONCATENATE("P",ROUNDDOWN((TablaOrganismo[Fecha Final de pago]-TablaTrabajadores[[#This Row],[Fecha Inicio Relación Laboral]])/7,0),"W")) -> P217W | Z2: =COUNTIF(TablaPercepciones[[#All],[Trabajador]],TablaTrabajadores[[#This Row],[Nombre Trabajador]]) -> 4 | AA2: =COUNTIF(TablaDeducciones[[#All],[Trabajador]],TablaTrabajadores[[#This Row],[Nombre Trabajador]]) -> 2 | AB2: =ROUND(IF((SUMIF(TablaPercepciones[[#All],[Trabajador]],TablaTrabajadores[[#This Row],[Nombre Trabajador]],TablaPercepciones[[#All],[Importe Gravado]]))=0,0,SUMIF(TablaPercepciones[[#All],[Trabajador]],TablaTrabajadores[[#This Row],[Nombre Trabajador]],TablaPercepciones[[#All],[Importe Gravado]])),2) -> #REF! | AC2: =ROUND(IF((SUMIF(TablaPercepciones[[#All],[Trabajador]],TablaTrabajadores[[#This Row],[Nombre Trabajador]],TablaPercepciones[[#All],[o]]))=0,0,SUMIF(TablaPercepciones[[#All],[Trabajador]],TablaTrabajadores[[#This Row],[Nombre Trabajador]],TablaPercepciones[[#All],[o]])),2) -> #REF! | AD2: =ROUND(IF(SUMIFS(TablaDeducciones[[#All],[Importe]],TablaDeducciones[[#All],[Trabajador]],TablaTrabajadores[[#This Row],[Nombre Trabajador]],TablaDeducciones[[#All],[Clave Deducción]],"<>002")=0,0,SUMIFS(TablaDeducciones[[#All],[Importe]],TablaDeducciones[[#All],[Trabajador]],TablaTrabajadores[[#This Row],[Nombre Trabajador]],TablaDeducciones[[#All],[Clave Deducción]],"<>002")),2) -> #REF! | AE2: =ROUND(IF((SUMIFS(TablaDeducciones[[#All],[Importe]],TablaDeducciones[[#All],[Trabajador]],TablaTrabajadores[[#This Row],[Nombre Trabajador]],TablaDeducciones[[#All],[Clave Deducción]],"=002"))=0,0,SUMIFS(TablaDeducciones[[#All],[Importe]],TablaDeducciones[[#All],[Trabajador]],TablaTrabajadores[[#This Row],[Nombre Trabajador]],TablaDeducciones[[#All],[Clave Deducción]],"=002")),2) -> 0 | AF2: =IF(TablaTrabajadores[[#This Row],[Origen del Recurso]]="","",VLOOKUP(TablaTrabajadores[[#This Row],[Origen del Recurso]],Cat!Y:Z,2,0)) -> IP | AG2: =IF(TablaTrabajadores[[#This Row],[Entidad Federativa]]="","",VLOOKUP(TablaTrabajadores[[#This Row],[Entidad Federativa]],Cat!AB:AC,2,0)) -> CHP | AH2: =COUNTIF(TablaHorasExtra[[#All],[Trabajador]],TablaTrabajadores[[#This Row],[Nombre Trabajador]]) -> 0 | AI2: =COUNTIF(TablaOtrosPagos[[#All],[Trabajador]],TablaTrabajadores[[#This Row],[Nombre Trabajador]]) -> 1 | AJ2: =IF(TablaTrabajadores[[#This Row],[Tipo de Jornada]]="","",VLOOKUP(TablaTrabajadores[[#This Row],[Tipo de Jornada]],Cat!AK:AL,2,0)) -> 1 | AK2: =ROUND(IFERROR(SUMIFS(TablaPercepciones[[#All],[Importe Gravado]],TablaPercepciones[[#All],[Trabajador]],TablaTrabajadores[[#This Row],[Nombre Trabajador]],TablaPercepciones[[#All],[Clave Percepción]],"<>022",TablaPercepciones[[#All],[Clave Percepción]],"<>023",TablaPercepciones[[#All],[Clave Percepción]],"<>025",TablaPercepciones[[#All],[Clave Percepción]],"<>044"),0)+IFERROR(SUMIFS(TablaPercepciones[[#All],[o]],TablaPercepciones[[#All],[Trabajador]],TablaTrabajadores[[#This Row],[Nombre Trabajador]],TablaPercepciones[[#All],[Clave Percepción]],"<>022",TablaPercepciones[[#All],[Clave Percepción]],"<>023",TablaPercepciones[[#All],[Clave Percepción]],"<>025",TablaPercepciones[[#All],[Clave Percepción]],"<>044"),0),2) -> 0 | AL2: =ROUND(IFERROR(SUMIFS(TablaPercepciones[[#All],[Importe Gravado]],TablaPercepciones[[#All],[Trabajador]],TablaTrabajadores[[#This Row],[Nombre Trabajador]],TablaPercepciones[[#All],[Clave Percepción]],"=022"),0)+IFERROR(SUMIFS(TablaPercepciones[[#All],[Importe Gravado]],TablaPercepciones[[#All],[Trabajador]],TablaTrabajadores[[#This Row],[Nombre Trabajador]],TablaPercepciones[[#All],[Clave Percepción]],"=023"),0)+IFERROR(SUMIFS(TablaPercepciones[[#All],[Importe Gravado]],TablaPercepciones[[#All],[Trabajador]],TablaTrabajadores[[#This Row],[Nombre Trabajador]],TablaPercepciones[[#All],[Clave Percepción]],"=025"),0)+IFERROR(SUMIFS(TablaPercepciones[[#All],[o]],TablaPercepciones[[#All],[Trabajador]],TablaTrabajadores[[#This Row],[Nombre Trabajador]],TablaPercepciones[[#All],[Clave Percepción]],"=022"),0)+IFERROR(SUMIFS(TablaPercepciones[[#All],[o]],TablaPercepciones[[#All],[Trabajador]],TablaTrabajadores[[#This Row],[Nombre Trabajador]],TablaPercepciones[[#All],[Clave Percepción]],"=023"),0)+IFERROR(SUMIFS(TablaPercepciones[[#All],[o]],TablaPercepciones[[#All],[Trabajador]],TablaTrabajadores[[#This Row],[Nombre Trabajador]],TablaPercepciones[[#All],[Clave Percepción]],"=025"),0),2) -> 0 | AM2: =ROUND(IFERROR(SUMIFS(TablaPercepciones[[#All],[Importe Gravado]],TablaPercepciones[[#All],[Trabajador]],TablaTrabajadores[[#This Row],[Nombre Trabajador]],TablaPercepciones[[#All],[Clave Percepción]],"=039"),0)+IFERROR(SUMIFS(TablaPercepciones[[#All],[Importe Gravado]],TablaPercepciones[[#All],[Trabajador]],TablaTrabajadores[[#This Row],[Nombre Trabajador]],TablaPercepciones[[#All],[Clave Percepción]],"=044"),0)+IFERROR(SUMIFS(TablaPercepciones[[#All],[o]],TablaPercepciones[[#All],[Trabajador]],TablaTrabajadores[[#This Row],[Nombre Trabajador]],TablaPercepciones[[#All],[Clave Percepción]],"=039"),0)+IFERROR(SUMIFS(TablaPercepciones[[#All],[o]],TablaPercepciones[[#All],[Trabajador]],TablaTrabajadores[[#This Row],[Nombre Trabajador]],TablaPercepciones[[#All],[Clave Percepción]],"=044"),0),2) -> 0 | AN2: Diurna
A3: 2 | B3: EICS720717IA8 | C3: ENRIQUEZ CONSTANTINO SILVIA | D3: EICS720717MCSNNL07 | E3: 71907233135 | F3: 43891 | G3: Contrato de trabajo por tiempo indeterminado | H3: Sueldos | I3: 5184 | J3: RECURSOS MATERIALES | K3: VELADOR | L3: 1 | M3: 157.26603 | N3: Ingresos propios | P3: Chiapas | Q3: canal10humanos@gmail.com | R3: canal10humanos@gmail.com | T3: =IF(TablaTrabajadores[[#This Row],[Tipo de Contrato]]="","",VLOOKUP(TablaTrabajadores[[#This Row],[Tipo de Contrato]],Cat!$G$1:$H$12,2,0)) -> 1 | U3: =IF(TablaTrabajadores[[#This Row],[Tipo de Régimen]]="","",VLOOKUP(TablaTrabajadores[[#This Row],[Tipo de Régimen]],Cat!$J$1:$K$13,2,0)) -> 2 | V3: =ROUND(IF((SUMIF(TablaPercepciones[[#All],[Trabajador]],TablaTrabajadores[[#This Row],[Nombre Trabajador]],TablaPercepciones[[#All],[Importe Gravado]])+SUMIF(TablaPercepciones[[#All],[Trabajador]],TablaTrabajadores[[#This Row],[Nombre Trabajador]],TablaPercepciones[[#All],[o]]))=0,0,SUMIF(TablaPercepciones[[#All],[Trabajador]],TablaTrabajadores[[#This Row],[Nombre Trabajador]],TablaPercepciones[[#All],[Importe Gravado]])+SUMIF(TablaPercepciones[[#All],[Trabajador]],TablaTrabajadores[[#This Row],[Nombre Trabajador]],TablaPercepciones[[#All],[o]])),2) -> #REF! | W3: =ROUND(IF((SUMIF(TablaDeducciones[[#All],[Trabajador]],TablaTrabajadores[[#This Row],[Nombre Trabajador]],TablaDeducciones[[#All],[Importe]]))=0,0,SUMIF(TablaDeducciones[[#All],[Trabajador]],TablaTrabajadores[[#This Row],[Nombre Trabajador]],TablaDeducciones[[#All],[Importe]])),2) -> 0 | X3: =ROUND(IF((SUMIF(TablaOtrosPagos[[#All],[Trabajador]],TablaTrabajadores[[#This Row],[Nombre Trabajador]],TablaOtrosPagos[[#All],[Importe]]))=0,0,SUMIF(TablaOtrosPagos[[#All],[Trabajador]],TablaTrabajadores[[#This Row],[Nombre Trabajador]],TablaOtrosPagos[[#All],[Importe]])),2) -> #REF! | Y3: =IF(OR(TablaOrganismo[Fecha Final de pago]="",TablaTrabajadores[[#This Row],[Fecha Inicio Relación Laboral]]=""),"",CONCATENATE("P",ROUNDDOWN((TablaOrganismo[Fecha Final de pago]-TablaTrabajadores[[#This Row],[Fecha Inicio Relación Laboral]])/7,0),"W")) -> P65W | Z3: =COUNTIF(TablaPercepciones[[#All],[Trabajador]],TablaTrabajadores[[#This Row],[Nombre Trabajador]]) -> 4 | AA3: =COUNTIF(TablaDeducciones[[#All],[Trabajador]],TablaTrabajadores[[#This Row],[Nombre Trabajador]]) -> 0 | AB3: =ROUND(IF((SUMIF(TablaPercepciones[[#All],[Trabajador]],TablaTrabajadores[[#This Row],[Nombre Trabajador]],TablaPercepciones[[#All],[Importe Gravado]]))=0,0,SUMIF(TablaPercepciones[[#All],[Trabajador]],TablaTrabajadores[[#This Row],[Nombre Trabajador]],TablaPercepciones[[#All],[Importe Gravado]])),2) -> #REF! | AC3: =ROUND(IF((SUMIF(TablaPercepciones[[#All],[Trabajador]],TablaTrabajadores[[#This Row],[Nombre Trabajador]],TablaPercepciones[[#All],[o]]))=0,0,SUMIF(TablaPercepciones[[#All],[Trabajador]],TablaTrabajadores[[#This Row],[Nombre Trabajador]],TablaPercepciones[[#All],[o]])),2) -> #REF! | AD3: =ROUND(IF(SUMIFS(TablaDeducciones[[#All],[Importe]],TablaDeducciones[[#All],[Trabajador]],TablaTrabajadores[[#This Row],[Nombre Trabajador]],TablaDeducciones[[#All],[Clave Deducción]],"<>002")=0,0,SUMIFS(TablaDeducciones[[#All],[Importe]],TablaDeducciones[[#All],[Trabajador]],TablaTrabajadores[[#This Row],[Nombre Trabajador]],TablaDeducciones[[#All],[Clave Deducción]],"<>002")),2) -> 0 | AE3: =ROUND(IF((SUMIFS(TablaDeducciones[[#All],[Importe]],TablaDeducciones[[#All],[Trabajador]],TablaTrabajadores[[#This Row],[Nombre Trabajador]],TablaDeducciones[[#All],[Clave Deducción]],"=002"))=0,0,SUMIFS(TablaDeducciones[[#All],[Importe]],TablaDeducciones[[#All],[Trabajador]],TablaTrabajadores[[#This Row],[Nombre Trabajador]],TablaDeducciones[[#All],[Clave Deducción]],"=002")),2) -> 0 | AF3: =IF(TablaTrabajadores[[#This Row],[Origen del Recurso]]="","",VLOOKUP(TablaTrabajadores[[#This Row],[Origen del Recurso]],Cat!Y:Z,2,0)) -> IP | AG3: =IF(TablaTrabajadores[[#This Row],[Entidad Federativa]]="","",VLOOKUP(TablaTrabajadores[[#This Row],[Entidad Federativa]],Cat!AB:AC,2,0)) -> CHP | AH3: =COUNTIF(TablaHorasExtra[[#All],[Trabajador]],TablaTrabajadores[[#This Row],[Nombre Trabajador]]) -> 0 | AI3: =COUNTIF(TablaOtrosPagos[[#All],[Trabajador]],TablaTrabajadores[[#This Row],[Nombre Trabajador]]) -> 1 | AJ3: =IF(TablaTrabajadores[[#This Row],[Tipo de Jornada]]="","",VLOOKUP(TablaTrabajadores[[#This Row],[Tipo de Jornada]],Cat!AK:AL,2,0)) -> 1 | AK3: =ROUND(IFERROR(SUMIFS(TablaPercepciones[[#All],[Importe Gravado]],TablaPercepciones[[#All],[Trabajador]],TablaTrabajadores[[#This Row],[Nombre Trabajador]],TablaPercepciones[[#All],[Clave Percepción]],"<>022",TablaPercepciones[[#All],[Clave Percepción]],"<>023",TablaPercepciones[[#All],[Clave Percepción]],"<>025",TablaPercepciones[[#All],[Clave Percepción]],"<>044"),0)+IFERROR(SUMIFS(TablaPercepciones[[#All],[o]],TablaPercepciones[[#All],[Trabajador]],TablaTrabajadores[[#This Row],[Nombre Trabajador]],TablaPercepciones[[#All],[Clave Percepción]],"<>022",TablaPercepciones[[#All],[Clave Percepción]],"<>023",TablaPercepciones[[#All],[Clave Percepción]],"<>025",TablaPercepciones[[#All],[Clave Percepción]],"<>044"),0),2) -> 0 | AL3: =ROUND(IFERROR(SUMIFS(TablaPercepciones[[#All],[Importe Gravado]],TablaPercepciones[[#All],[Trabajador]],TablaTrabajadores[[#This Row],[Nombre Trabajador]],TablaPercepciones[[#All],[Clave Percepción]],"=022"),0)+IFERROR(SUMIFS(TablaPercepciones[[#All],[Importe Gravado]],TablaPercepciones[[#All],[Trabajador]],TablaTrabajadores[[#This Row],[Nombre Trabajador]],TablaPercepciones[[#All],[Clave Percepción]],"=023"),0)+IFERROR(SUMIFS(TablaPercepciones[[#All],[Importe Gravado]],TablaPercepciones[[#All],[Trabajador]],TablaTrabajadores[[#This Row],[Nombre Trabajador]],TablaPercepciones[[#All],[Clave Percepción]],"=025"),0)+IFERROR(SUMIFS(TablaPercepciones[[#All],[o]],TablaPercepciones[[#All],[Trabajador]],TablaTrabajadores[[#This Row],[Nombre Trabajador]],TablaPercepciones[[#All],[Clave Percepción]],"=022"),0)+IFERROR(SUMIFS(TablaPercepciones[[#All],[o]],TablaPercepciones[[#All],[Trabajador]],TablaTrabajadores[[#This Row],[Nombre Trabajador]],TablaPercepciones[[#All],[Clave Percepción]],"=023"),0)+IFERROR(SUMIFS(TablaPercepciones[[#All],[o]],TablaPercepciones[[#All],[Trabajador]],TablaTrabajadores[[#This Row],[Nombre Trabajador]],TablaPercepciones[[#All],[Clave Percepción]],"=025"),0),2) -> 0 | AM3: =ROUND(IFERROR(SUMIFS(TablaPercepciones[[#All],[Importe Gravado]],TablaPercepciones[[#All],[Trabajador]],TablaTrabajadores[[#This Row],[Nombre Trabajador]],TablaPercepciones[[#All],[Clave Percepción]],"=039"),0)+IFERROR(SUMIFS(TablaPercepciones[[#All],[Importe Gravado]],TablaPercepciones[[#All],[Trabajador]],TablaTrabajadores[[#This Row],[Nombre Trabajador]],TablaPercepciones[[#All],[Clave Percepción]],"=044"),0)+IFERROR(SUMIFS(TablaPercepciones[[#All],[o]],TablaPercepciones[[#All],[Trabajador]],TablaTrabajadores[[#This Row],[Nombre Trabajador]],TablaPercepciones[[#All],[Clave Percepción]],"=039"),0)+IFERROR(SUMIFS(TablaPercepciones[[#All],[o]],TablaPercepciones[[#All],[Trabajador]],TablaTrabajadores[[#This Row],[Nombre Trabajador]],TablaPercepciones[[#All],[Clave Percepción]],"=044"),0),2) -> 0 | AN3: Diurna
A4: 3 | B4: GOHS770725VE9 | C4: GOMEZ HERNANDEZ SANTIAGO CRISTOBAL | D4: GOHS770725HCSMRN04 | E4: 71937743913 | F4: 38169 | G4: Contrato de trabajo por tiempo indeterminado | H4: Sueldos | I4: 88 | J4: ESTACION TV SAN CRISTOBAL XHSBB TV | K4: VELADOR | L4: 1 | M4: 157.76034 | N4: Ingresos propios | P4: Chiapas | Q4: canal10humanos@gmail.com | R4: canal10humanos@gmail.com | T4: =IF(TablaTrabajadores[[#This Row],[Tipo de Contrato]]="","",VLOOKUP(TablaTrabajadores[[#This Row],[Tipo de Contrato]],Cat!$G$1:$H$12,2,0)) -> 1 | U4: =IF(TablaTrabajadores[[#This Row],[Tipo de Régimen]]="","",VLOOKUP(TablaTrabajadores[[#This Row],[Tipo de Régimen]],Cat!$J$1:$K$13,2,0)) -> 2 | V4: =ROUND(IF((SUMIF(TablaPercepciones[[#All],[Trabajador]],TablaTrabajadores[[#This Row],[Nombre Trabajador]],TablaPercepciones[[#All],[Importe Gravado]])+SUMIF(TablaPercepciones[[#All],[Trabajador]],TablaTrabajadores[[#This Row],[Nombre Trabajador]],TablaPercepciones[[#All],[o]]))=0,0,SUMIF(TablaPercepciones[[#All],[Trabajador]],TablaTrabajadores[[#This Row],[Nombre Trabajador]],TablaPercepciones[[#All],[Importe Gravado]])+SUMIF(TablaPercepciones[[#All],[Trabajador]],TablaTrabajadores[[#This Row],[Nombre Trabajador]],TablaPercepciones[[#All],[o]])),2) -> #REF! | W4: =ROUND(IF((SUMIF(TablaDeducciones[[#All],[Trabajador]],TablaTrabajadores[[#This Row],[Nombre Trabajador]],TablaDeducciones[[#All],[Importe]]))=0,0,SUMIF(TablaDeducciones[[#All],[Trabajador]],TablaTrabajadores[[#This Row],[Nombre Trabajador]],TablaDeducciones[[#All],[Importe]])),2) -> #REF! | X4: =ROUND(IF((SUMIF(TablaOtrosPagos[[#All],[Trabajador]],TablaTrabajadores[[#This Row],[Nombre Trabajador]],TablaOtrosPagos[[#All],[Importe]]))=0,0,SUMIF(TablaOtrosPagos[[#All],[Trabajador]],TablaTrabajadores[[#This Row],[Nombre Trabajador]],TablaOtrosPagos[[#All],[Importe]])),2) -> #REF! | Y4: =IF(OR(TablaOrganismo[Fecha Final de pago]="",TablaTrabajadores[[#This Row],[Fecha Inicio Relación Laboral]]=""),"",CONCATENATE("P",ROUNDDOWN((TablaOrganismo[Fecha Final de pago]-TablaTrabajadores[[#This Row],[Fecha Inicio Relación Laboral]])/7,0),"W")) -> P882W | Z4: =COUNTIF(TablaPercepciones[[#All],[Trabajador]],TablaTrabajadores[[#This Row],[Nombre Trabajador]]) -> 4 | AA4: =COUNTIF(TablaDeducciones[[#All],[Trabajador]],TablaTrabajadores[[#This Row],[Nombre Trabajador]]) -> 1 | AB4: =ROUND(IF((SUMIF(TablaPercepciones[[#All],[Trabajador]],TablaTrabajadores[[#This Row],[Nombre Trabajador]],TablaPercepciones[[#All],[Importe Gravado]]))=0,0,SUMIF(TablaPercepciones[[#All],[Trabajador]],TablaTrabajadores[[#This Row],[Nombre Trabajador]],TablaPercepciones[[#All],[Importe Gravado]])),2) -> #REF! | AC4: =ROUND(IF((SUMIF(TablaPercepciones[[#All],[Trabajador]],TablaTrabajadores[[#This Row],[Nombre Trabajador]],TablaPercepciones[[#All],[o]]))=0,0,SUMIF(TablaPercepciones[[#All],[Trabajador]],TablaTrabajadores[[#This Row],[Nombre Trabajador]],TablaPercepciones[[#All],[o]])),2) -> #REF! | AD4: =ROUND(IF(SUMIFS(TablaDeducciones[[#All],[Importe]],TablaDeducciones[[#All],[Trabajador]],TablaTrabajadores[[#This Row],[Nombre Trabajador]],TablaDeducciones[[#All],[Clave Deducción]],"<>002")=0,0,SUMIFS(TablaDeducciones[[#All],[Importe]],TablaDeducciones[[#All],[Trabajador]],TablaTrabajadores[[#This Row],[Nombre Trabajador]],TablaDeducciones[[#All],[Clave Deducción]],"<>002")),2) -> #REF! | AE4: =ROUND(IF((SUMIFS(TablaDeducciones[[#All],[Importe]],TablaDeducciones[[#All],[Trabajador]],TablaTrabajadores[[#This Row],[Nombre Trabajador]],TablaDeducciones[[#All],[Clave Deducción]],"=002"))=0,0,SUMIFS(TablaDeducciones[[#All],[Importe]],TablaDeducciones[[#All],[Trabajador]],TablaTrabajadores[[#This Row],[Nombre Trabajador]],TablaDeducciones[[#All],[Clave Deducción]],"=002")),2) -> 0 | AF4: =IF(TablaTrabajadores[[#This Row],[Origen del Recurso]]="","",VLOOKUP(TablaTrabajadores[[#This Row],[Origen del Recurso]],Cat!Y:Z,2,0)) -> IP | AG4: =IF(TablaTrabajadores[[#This Row],[Entidad Federativa]]="","",VLOOKUP(TablaTrabajadores[[#This Row],[Entidad Federativa]],Cat!AB:AC,2,0)) -> CHP | AH4: =COUNTIF(TablaHorasExtra[[#All],[Trabajador]],TablaTrabajadores[[#This Row],[Nombre Trabajador]]) -> 0 | AI4: =COUNTIF(TablaOtrosPagos[[#All],[Trabajador]],TablaTrabajadores[[#This Row],[Nombre Trabajador]]) -> 1 | AJ4: =IF(TablaTrabajadores[[#This Row],[Tipo de Jornada]]="","",VLOOKUP(TablaTrabajadores[[#This Row],[Tipo de Jornada]],Cat!AK:AL,2,0)) -> 1 | AK4: =ROUND(IFERROR(SUMIFS(TablaPercepciones[[#All],[Importe Gravado]],TablaPercepciones[[#All],[Trabajador]],TablaTrabajadores[[#This Row],[Nombre Trabajador]],TablaPercepciones[[#All],[Clave Percepción]],"<>022",TablaPercepciones[[#All],[Clave Percepción]],"<>023",TablaPercepciones[[#All],[Clave Percepción]],"<>025",TablaPercepciones[[#All],[Clave Percepción]],"<>044"),0)+IFERROR(SUMIFS(TablaPercepciones[[#All],[o]],TablaPercepciones[[#All],[Trabajador]],TablaTrabajadores[[#This Row],[Nombre Trabajador]],TablaPercepciones[[#All],[Clave Percepción]],"<>022",TablaPercepciones[[#All],[Clave Percepción]],"<>023",TablaPercepciones[[#All],[Clave Percepción]],"<>025",TablaPercepciones[[#All],[Clave Percepción]],"<>044"),0),2) -> 0 | AL4: =ROUND(IFERROR(SUMIFS(TablaPercepciones[[#All],[Importe Gravado]],TablaPercepciones[[#All],[Trabajador]],TablaTrabajadores[[#This Row],[Nombre Trabajador]],TablaPercepciones[[#All],[Clave Percepción]],"=022"),0)+IFERROR(SUMIFS(TablaPercepciones[[#All],[Importe Gravado]],TablaPercepciones[[#All],[Trabajador]],TablaTrabajadores[[#This Row],[Nombre Trabajador]],TablaPercepciones[[#All],[Clave Percepción]],"=023"),0)+IFERROR(SUMIFS(TablaPercepciones[[#All],[Importe Gravado]],TablaPercepciones[[#All],[Trabajador]],TablaTrabajadores[[#This Row],[Nombre Trabajador]],TablaPercepciones[[#All],[Clave Percepción]],"=025"),0)+IFERROR(SUMIFS(TablaPercepciones[[#All],[o]],TablaPercepciones[[#All],[Trabajador]],TablaTrabajadores[[#This Row],[Nombre Trabajador]],TablaPercepciones[[#All],[Clave Percepción]],"=022"),0)+IFERROR(SUMIFS(TablaPercepciones[[#All],[o]],TablaPercepciones[[#All],[Trabajador]],TablaTrabajadores[[#This Row],[Nombre Trabajador]],TablaPercepciones[[#All],[Clave Percepción]],"=023"),0)+IFERROR(SUMIFS(TablaPercepciones[[#All],[o]],TablaPercepciones[[#All],[Trabajador]],TablaTrabajadores[[#This Row],[Nombre Trabajador]],TablaPercepciones[[#All],[Clave Percepción]],"=025"),0),2) -> 0 | AM4: =ROUND(IFERROR(SUMIFS(TablaPercepciones[[#All],[Importe Gravado]],TablaPercepciones[[#All],[Trabajador]],TablaTrabajadores[[#This Row],[Nombre Trabajador]],TablaPercepciones[[#All],[Clave Percepción]],"=039"),0)+IFERROR(SUMIFS(TablaPercepciones[[#All],[Importe Gravado]],TablaPercepciones[[#All],[Trabajador]],TablaTrabajadores[[#This Row],[Nombre Trabajador]],TablaPercepciones[[#All],[Clave Percepción]],"=044"),0)+IFERROR(SUMIFS(TablaPercepciones[[#All],[o]],TablaPercepciones[[#All],[Trabajador]],TablaTrabajadores[[#This Row],[Nombre Trabajador]],TablaPercepciones[[#All],[Clave Percepción]],"=039"),0)+IFERROR(SUMIFS(TablaPercepciones[[#All],[o]],TablaPercepciones[[#All],[Trabajador]],TablaTrabajadores[[#This Row],[Nombre Trabajador]],TablaPercepciones[[#All],[Clave Percepción]],"=044"),0),2) -> 0 | AN4: Diurna
A5: 4 | B5: GOLJ580310TC2 | C5: GOMEZ LOPEZ JUAN | D5: GOLJ580310HCSMPN02 | E5: 71755801777 | F5: 37104 | G5: Contrato de trabajo por tiempo indeterminado | H5: Sueldos | I5: 60 | J5: OFICINA DE PRODUCCION | K5: CONDUCTOR A | L5: 1 | M5: 167.06316 | N5: Ingresos propios | P5: Chiapas | Q5: xuntsima_1@hotmail.com | R5: canal10humanos@gmail.com | T5: =IF(TablaTrabajadores[[#This Row],[Tipo de Contrato]]="","",VLOOKUP(TablaTrabajadores[[#This Row],[Tipo de Contrato]],Cat!$G$1:$H$12,2,0)) -> 1 | U5: =IF(TablaTrabajadores[[#This Row],[Tipo de Régimen]]="","",VLOOKUP(TablaTrabajadores[[#This Row],[Tipo de Régimen]],Cat!$J$1:$K$13,2,0)) -> 2 | V5: =ROUND(IF((SUMIF(TablaPercepciones[[#All],[Trabajador]],TablaTrabajadores[[#This Row],[Nombre Trabajador]],TablaPercepciones[[#All],[Importe Gravado]])+SUMIF(TablaPercepciones[[#All],[Trabajador]],TablaTrabajadores[[#This Row],[Nombre Trabajador]],TablaPercepciones[[#All],[o]]))=0,0,SUMIF(TablaPercepciones[[#All],[Trabajador]],TablaTrabajadores[[#This Row],[Nombre Trabajador]],TablaPercepciones[[#All],[Importe Gravado]])+SUMIF(TablaPercepciones[[#All],[Trabajador]],TablaTrabajadores[[#This Row],[Nombre Trabajador]],TablaPercepciones[[#All],[o]])),2) -> #REF! | W5: =ROUND(IF((SUMIF(TablaDeducciones[[#All],[Trabajador]],TablaTrabajadores[[#This Row],[Nombre Trabajador]],TablaDeducciones[[#All],[Importe]]))=0,0,SUMIF(TablaDeducciones[[#All],[Trabajador]],TablaTrabajadores[[#This Row],[Nombre Trabajador]],TablaDeducciones[[#All],[Importe]])),2) -> #REF! | X5: =ROUND(IF((SUMIF(TablaOtrosPagos[[#All],[Trabajador]],TablaTrabajadores[[#This Row],[Nombre Trabajador]],TablaOtrosPagos[[#All],[Importe]]))=0,0,SUMIF(TablaOtrosPagos[[#All],[Trabajador]],TablaTrabajadores[[#This Row],[Nombre Trabajador]],TablaOtrosPagos[[#All],[Importe]])),2) -> #REF! | Y5: =IF(OR(TablaOrganismo[Fecha Final de pago]="",TablaTrabajadores[[#This Row],[Fecha Inicio Relación Laboral]]=""),"",CONCATENATE("P",ROUNDDOWN((TablaOrganismo[Fecha Final de pago]-TablaTrabajadores[[#This Row],[Fecha Inicio Relación Laboral]])/7,0),"W")) -> P1034W | Z5: =COUNTIF(TablaPercepciones[[#All],[Trabajador]],TablaTrabajadores[[#This Row],[Nombre Trabajador]]) -> 4 | AA5: =COUNTIF(TablaDeducciones[[#All],[Trabajador]],TablaTrabajadores[[#This Row],[Nombre Trabajador]]) -> 1 | AB5: =ROUND(IF((SUMIF(TablaPercepciones[[#All],[Trabajador]],TablaTrabajadores[[#This Row],[Nombre Trabajador]],TablaPercepciones[[#All],[Importe Gravado]]))=0,0,SUMIF(TablaPercepciones[[#All],[Trabajador]],TablaTrabajadores[[#This Row],[Nombre Trabajador]],TablaPercepciones[[#All],[Importe Gravado]])),2) -> #REF! | AC5: =ROUND(IF((SUMIF(TablaPercepciones[[#All],[Trabajador]],TablaTrabajadores[[#This Row],[Nombre Trabajador]],TablaPercepciones[[#All],[o]]))=0,0,SUMIF(TablaPercepciones[[#All],[Trabajador]],TablaTrabajadores[[#This Row],[Nombre Trabajador]],TablaPercepciones[[#All],[o]])),2) -> #REF! | AD5: =ROUND(IF(SUMIFS(TablaDeducciones[[#All],[Importe]],TablaDeducciones[[#All],[Trabajador]],TablaTrabajadores[[#This Row],[Nombre Trabajador]],TablaDeducciones[[#All],[Clave Deducción]],"<>002")=0,0,SUMIFS(TablaDeducciones[[#All],[Importe]],TablaDeducciones[[#All],[Trabajador]],TablaTrabajadores[[#This Row],[Nombre Trabajador]],TablaDeducciones[[#All],[Clave Deducción]],"<>002")),2) -> #REF! | AE5: =ROUND(IF((SUMIFS(TablaDeducciones[[#All],[Importe]],TablaDeducciones[[#All],[Trabajador]],TablaTrabajadores[[#This Row],[Nombre Trabajador]],TablaDeducciones[[#All],[Clave Deducción]],"=002"))=0,0,SUMIFS(TablaDeducciones[[#All],[Importe]],TablaDeducciones[[#All],[Trabajador]],TablaTrabajadores[[#This Row],[Nombre Trabajador]],TablaDeducciones[[#All],[Clave Deducción]],"=002")),2) -> 0 | AF5: =IF(TablaTrabajadores[[#This Row],[Origen del Recurso]]="","",VLOOKUP(TablaTrabajadores[[#This Row],[Origen del Recurso]],Cat!Y:Z,2,0)) -> IP | AG5: =IF(TablaTrabajadores[[#This Row],[Entidad Federativa]]="","",VLOOKUP(TablaTrabajadores[[#This Row],[Entidad Federativa]],Cat!AB:AC,2,0)) -> CHP | AH5: =COUNTIF(TablaHorasExtra[[#All],[Trabajador]],TablaTrabajadores[[#This Row],[Nombre Trabajador]]) -> 0 | AI5: =COUNTIF(TablaOtrosPagos[[#All],[Trabajador]],TablaTrabajadores[[#This Row],[Nombre Trabajador]]) -> 1 | AJ5: =IF(TablaTrabajadores[[#This Row],[Tipo de Jornada]]="","",VLOOKUP(TablaTrabajadores[[#This Row],[Tipo de Jornada]],Cat!AK:AL,2,0)) -> 1 | AK5: =ROUND(IFERROR(SUMIFS(TablaPercepciones[[#All],[Importe Gravado]],TablaPercepciones[[#All],[Trabajador]],TablaTrabajadores[[#This Row],[Nombre Trabajador]],TablaPercepciones[[#All],[Clave Percepción]],"<>022",TablaPercepciones[[#All],[Clave Percepción]],"<>023",TablaPercepciones[[#All],[Clave Percepción]],"<>025",TablaPercepciones[[#All],[Clave Percepción]],"<>044"),0)+IFERROR(SUMIFS(TablaPercepciones[[#All],[o]],TablaPercepciones[[#All],[Trabajador]],TablaTrabajadores[[#This Row],[Nombre Trabajador]],TablaPercepciones[[#All],[Clave Percepción]],"<>022",TablaPercepciones[[#All],[Clave Percepción]],"<>023",TablaPercepciones[[#All],[Clave Percepción]],"<>025",TablaPercepciones[[#All],[Clave Percepción]],"<>044"),0),2) -> 0 | AL5: =ROUND(IFERROR(SUMIFS(TablaPercepciones[[#All],[Importe Gravado]],TablaPercepciones[[#All],[Trabajador]],TablaTrabajadores[[#This Row],[Nombre Trabajador]],TablaPercepciones[[#All],[Clave Percepción]],"=022"),0)+IFERROR(SUMIFS(TablaPercepciones[[#All],[Importe Gravado]],TablaPercepciones[[#All],[Trabajador]],TablaTrabajadores[[#This Row],[Nombre Trabajador]],TablaPercepciones[[#All],[Clave Percepción]],"=023"),0)+IFERROR(SUMIFS(TablaPercepciones[[#All],[Importe Gravado]],TablaPercepciones[[#All],[Trabajador]],TablaTrabajadores[[#This Row],[Nombre Trabajador]],TablaPercepciones[[#All],[Clave Percepción]],"=025"),0)+IFERROR(SUMIFS(TablaPercepciones[[#All],[o]],TablaPercepciones[[#All],[Trabajador]],TablaTrabajadores[[#This Row],[Nombre Trabajador]],TablaPercepciones[[#All],[Clave Percepción]],"=022"),0)+IFERROR(SUMIFS(TablaPercepciones[[#All],[o]],TablaPercepciones[[#All],[Trabajador]],TablaTrabajadores[[#This Row],[Nombre Trabajador]],TablaPercepciones[[#All],[Clave Percepción]],"=023"),0)+IFERROR(SUMIFS(TablaPercepciones[[#All],[o]],TablaPercepciones[[#All],[Trabajador]],TablaTrabajadores[[#This Row],[Nombre Trabajador]],TablaPercepciones[[#All],[Clave Percepción]],"=025"),0),2) -> 0 | AM5: =ROUND(IFERROR(SUMIFS(TablaPercepciones[[#All],[Importe Gravado]],TablaPercepciones[[#All],[Trabajador]],TablaTrabajadores[[#This Row],[Nombre Trabajador]],TablaPercepciones[[#All],[Clave Percepción]],"=039"),0)+IFERROR(SUMIFS(TablaPercepciones[[#All],[Importe Gravado]],TablaPercepciones[[#All],[Trabajador]],TablaTrabajadores[[#This Row],[Nombre Trabajador]],TablaPercepciones[[#All],[Clave Percepción]],"=044"),0)+IFERROR(SUMIFS(TablaPercepciones[[#All],[o]],TablaPercepciones[[#All],[Trabajador]],TablaTrabajadores[[#This Row],[Nombre Trabajador]],TablaPercepciones[[#All],[Clave Percepción]],"=039"),0)+IFERROR(SUMIFS(TablaPercepciones[[#All],[o]],TablaPercepciones[[#All],[Trabajador]],TablaTrabajadores[[#This Row],[Nombre Trabajador]],TablaPercepciones[[#All],[Clave Percepción]],"=044"),0),2) -> 0 | AN5: Diurna
A6: 5 | B6: GOAE930619LGA | C6: GONZALEZ ARCE EDUARDO | D6: GOAE930619HCSNRD05 | E6: 71139306915 | F6: 42902 | G6: Contrato de trabajo por tiempo indeterminado | H6: Sueldos | I6: 986 | J6: DEPARTAMENTO DE PRODUCCION DE NOTICIAS | K6: CHOFER DE APOYO | L6: 1 | M6: 201.81754 | N6: Ingresos propios | P6: Chiapas | Q6: vksip19@gmail.com | R6: canal10humanos@gmail.com | T6: =IF(TablaTrabajadores[[#This Row],[Tipo de Contrato]]="","",VLOOKUP(TablaTrabajadores[[#This Row],[Tipo de Contrato]],Cat!$G$1:$H$12,2,0)) -> 1 | U6: =IF(TablaTrabajadores[[#This Row],[Tipo de Régimen]]="","",VLOOKUP(TablaTrabajadores[[#This Row],[Tipo de Régimen]],Cat!$J$1:$K$13,2,0)) -> 2 | V6: =ROUND(IF((SUMIF(TablaPercepciones[[#All],[Trabajador]],TablaTrabajadores[[#This Row],[Nombre Trabajador]],TablaPercepciones[[#All],[Importe Gravado]])+SUMIF(TablaPercepciones[[#All],[Trabajador]],TablaTrabajadores[[#This Row],[Nombre Trabajador]],TablaPercepciones[[#All],[o]]))=0,0,SUMIF(TablaPercepciones[[#All],[Trabajador]],TablaTrabajadores[[#This Row],[Nombre Trabajador]],TablaPercepciones[[#All],[Importe Gravado]])+SUMIF(TablaPercepciones[[#All],[Trabajador]],TablaTrabajadores[[#This Row],[Nombre Trabajador]],TablaPercepciones[[#All],[o]])),2) -> #REF! | W6: =ROUND(IF((SUMIF(TablaDeducciones[[#All],[Trabajador]],TablaTrabajadores[[#This Row],[Nombre Trabajador]],TablaDeducciones[[#All],[Importe]]))=0,0,SUMIF(TablaDeducciones[[#All],[Trabajador]],TablaTrabajadores[[#This Row],[Nombre Trabajador]],TablaDeducciones[[#All],[Importe]])),2) -> #REF! | X6: =ROUND(IF((SUMIF(TablaOtrosPagos[[#All],[Trabajador]],TablaTrabajadores[[#This Row],[Nombre Trabajador]],TablaOtrosPagos[[#All],[Importe]]))=0,0,SUMIF(TablaOtrosPagos[[#All],[Trabajador]],TablaTrabajadores[[#This Row],[Nombre Trabajador]],TablaOtrosPagos[[#All],[Importe]])),2) -> #REF! | Y6: =IF(OR(TablaOrganismo[Fecha Final de pago]="",TablaTrabajadores[[#This Row],[Fecha Inicio Relación Laboral]]=""),"",CONCATENATE("P",ROUNDDOWN((TablaOrganismo[Fecha Final de pago]-TablaTrabajadores[[#This Row],[Fecha Inicio Relación Laboral]])/7,0),"W")) -> P206W | Z6: =COUNTIF(TablaPercepciones[[#All],[Trabajador]],TablaTrabajadores[[#This Row],[Nombre Trabajador]]) -> 4 | AA6: =COUNTIF(TablaDeducciones[[#All],[Trabajador]],TablaTrabajadores[[#This Row],[Nombre Trabajador]]) -> 2 | AB6: =ROUND(IF((SUMIF(TablaPercepciones[[#All],[Trabajador]],TablaTrabajadores[[#This Row],[Nombre Trabajador]],TablaPercepciones[[#All],[Importe Gravado]]))=0,0,SUMIF(TablaPercepciones[[#All],[Trabajador]],TablaTrabajadores[[#This Row],[Nombre Trabajador]],TablaPercepciones[[#All],[Importe Gravado]])),2) -> #REF! | AC6: =ROUND(IF((SUMIF(TablaPercepciones[[#All],[Trabajador]],TablaTrabajadores[[#This Row],[Nombre Trabajador]],TablaPercepciones[[#All],[o]]))=0,0,SUMIF(TablaPercepciones[[#All],[Trabajador]],TablaTrabajadores[[#This Row],[Nombre Trabajador]],TablaPercepciones[[#All],[o]])),2) -> #REF! | AD6: =ROUND(IF(SUMIFS(TablaDeducciones[[#All],[Importe]],TablaDeducciones[[#All],[Trabajador]],TablaTrabajadores[[#This Row],[Nombre Trabajador]],TablaDeducciones[[#All],[Clave Deducción]],"<>002")=0,0,SUMIFS(TablaDeducciones[[#All],[Importe]],TablaDeducciones[[#All],[Trabajador]],TablaTrabajadores[[#This Row],[Nombre Trabajador]],TablaDeducciones[[#All],[Clave Deducción]],"<>002")),2) -> #REF! | AE6: =ROUND(IF((SUMIFS(TablaDeducciones[[#All],[Importe]],TablaDeducciones[[#All],[Trabajador]],TablaTrabajadores[[#This Row],[Nombre Trabajador]],TablaDeducciones[[#All],[Clave Deducción]],"=002"))=0,0,SUMIFS(TablaDeducciones[[#All],[Importe]],TablaDeducciones[[#All],[Trabajador]],TablaTrabajadores[[#This Row],[Nombre Trabajador]],TablaDeducciones[[#All],[Clave Deducción]],"=002")),2) -> 0 | AF6: =IF(TablaTrabajadores[[#This Row],[Origen del Recurso]]="","",VLOOKUP(TablaTrabajadores[[#This Row],[Origen del Recurso]],Cat!Y:Z,2,0)) -> IP | AG6: =IF(TablaTrabajadores[[#This Row],[Entidad Federativa]]="","",VLOOKUP(TablaTrabajadores[[#This Row],[Entidad Federativa]],Cat!AB:AC,2,0)) -> CHP | AH6: =COUNTIF(TablaHorasExtra[[#All],[Trabajador]],TablaTrabajadores[[#This Row],[Nombre Trabajador]]) -> 0 | AI6: =COUNTIF(TablaOtrosPagos[[#All],[Trabajador]],TablaTrabajadores[[#This Row],[Nombre Trabajador]]) -> 1 | AJ6: =IF(TablaTrabajadores[[#This Row],[Tipo de Jornada]]="","",VLOOKUP(TablaTrabajadores[[#This Row],[Tipo de Jornada]],Cat!AK:AL,2,0)) -> 3 | AK6: =ROUND(IFERROR(SUMIFS(TablaPercepciones[[#All],[Importe Gravado]],TablaPercepciones[[#All],[Trabajador]],TablaTrabajadores[[#This Row],[Nombre Trabajador]],TablaPercepciones[[#All],[Clave Percepción]],"<>022",TablaPercepciones[[#All],[Clave Percepción]],"<>023",TablaPercepciones[[#All],[Clave Percepción]],"<>025",TablaPercepciones[[#All],[Clave Percepción]],"<>044"),0)+IFERROR(SUMIFS(TablaPercepciones[[#All],[o]],TablaPercepciones[[#All],[Trabajador]],TablaTrabajadores[[#This Row],[Nombre Trabajador]],TablaPercepciones[[#All],[Clave Percepción]],"<>022",TablaPercepciones[[#All],[Clave Percepción]],"<>023",TablaPercepciones[[#All],[Clave Percepción]],"<>025",TablaPercepciones[[#All],[Clave Percepción]],"<>044"),0),2) -> 0 | AL6: =ROUND(IFERROR(SUMIFS(TablaPercepciones[[#All],[Importe Gravado]],TablaPercepciones[[#All],[Trabajador]],TablaTrabajadores[[#This Row],[Nombre Trabajador]],TablaPercepciones[[#All],[Clave Percepción]],"=022"),0)+IFERROR(SUMIFS(TablaPercepciones[[#All],[Importe Gravado]],TablaPercepciones[[#All],[Trabajador]],TablaTrabajadores[[#This Row],[Nombre Trabajador]],TablaPercepciones[[#All],[Clave Percepción]],"=023"),0)+IFERROR(SUMIFS(TablaPercepciones[[#All],[Importe Gravado]],TablaPercepciones[[#All],[Trabajador]],TablaTrabajadores[[#This Row],[Nombre Trabajador]],TablaPercepciones[[#All],[Clave Percepción]],"=025"),0)+IFERROR(SUMIFS(TablaPercepciones[[#All],[o]],TablaPercepciones[[#All],[Trabajador]],TablaTrabajadores[[#This Row],[Nombre Trabajador]],TablaPercepciones[[#All],[Clave Percepción]],"=022"),0)+IFERROR(SUMIFS(TablaPercepciones[[#All],[o]],TablaPercepciones[[#All],[Trabajador]],TablaTrabajadores[[#This Row],[Nombre Trabajador]],TablaPercepciones[[#All],[Clave Percepción]],"=023"),0)+IFERROR(SUMIFS(TablaPercepciones[[#All],[o]],TablaPercepciones[[#All],[Trabajador]],TablaTrabajadores[[#This Row],[Nombre Trabajador]],TablaPercepciones[[#All],[Clave Percepción]],"=025"),0),2) -> 0 | AM6: =ROUND(IFERROR(SUMIFS(TablaPercepciones[[#All],[Importe Gravado]],TablaPercepciones[[#All],[Trabajador]],TablaTrabajadores[[#This Row],[Nombre Trabajador]],TablaPercepciones[[#All],[Clave Percepción]],"=039"),0)+IFERROR(SUMIFS(TablaPercepciones[[#All],[Importe Gravado]],TablaPercepciones[[#All],[Trabajador]],TablaTrabajadores[[#This Row],[Nombre Trabajador]],TablaPercepciones[[#All],[Clave Percepción]],"=044"),0)+IFERROR(SUMIFS(TablaPercepciones[[#All],[o]],TablaPercepciones[[#All],[Trabajador]],TablaTrabajadores[[#This Row],[Nombre Trabajador]],TablaPercepciones[[#All],[Clave Percepción]],"=039"),0)+IFERROR(SUMIFS(TablaPercepciones[[#All],[o]],TablaPercepciones[[#All],[Trabajador]],TablaTrabajadores[[#This Row],[Nombre Trabajador]],TablaPercepciones[[#All],[Clave Percepción]],"=044"),0),2) -> 0 | AN6: Mixta
A7: 6 | B7: LEAS8208289V1 | C7: LEEP ARRIAGA SEMEIN AGUSTIN | D7: LEAS820828HCSPRM09 | E7: 71118205427 | F7: 42917 | G7: Contrato de trabajo por tiempo indeterminado | H7: Sueldos | I7: 991 | J7: REPETIDORA TV LACANJA CHANSAYAB XHITC TV | K7: VELADOR | L7: 1 | M7: 157.26603 | N7: Ingresos propios | P7: Chiapas | Q7: gallito_compositor@hotmail.com | R7: canal10humanos@gmail.com | T7: =IF(TablaTrabajadores[[#This Row],[Tipo de Contrato]]="","",VLOOKUP(TablaTrabajadores[[#This Row],[Tipo de Contrato]],Cat!$G$1:$H$12,2,0)) -> 1 | U7: =IF(TablaTrabajadores[[#This Row],[Tipo de Régimen]]="","",VLOOKUP(TablaTrabajadores[[#This Row],[Tipo de Régimen]],Cat!$J$1:$K$13,2,0)) -> 2 | V7: =ROUND(IF((SUMIF(TablaPercepciones[[#All],[Trabajador]],TablaTrabajadores[[#This Row],[Nombre Trabajador]],TablaPercepciones[[#All],[Importe Gravado]])+SUMIF(TablaPercepciones[[#All],[Trabajador]],TablaTrabajadores[[#This Row],[Nombre Trabajador]],TablaPercepciones[[#All],[o]]))=0,0,SUMIF(TablaPercepciones[[#All],[Trabajador]],TablaTrabajadores[[#This Row],[Nombre Trabajador]],TablaPercepciones[[#All],[Importe Gravado]])+SUMIF(TablaPercepciones[[#All],[Trabajador]],TablaTrabajadores[[#This Row],[Nombre Trabajador]],TablaPercepciones[[#All],[o]])),2) -> #REF! | W7: =ROUND(IF((SUMIF(TablaDeducciones[[#All],[Trabajador]],TablaTrabajadores[[#This Row],[Nombre Trabajador]],TablaDeducciones[[#All],[Importe]]))=0,0,SUMIF(TablaDeducciones[[#All],[Trabajador]],TablaTrabajadores[[#This Row],[Nombre Trabajador]],TablaDeducciones[[#All],[Importe]])),2) -> #REF! | X7: =ROUND(IF((SUMIF(TablaOtrosPagos[[#All],[Trabajador]],TablaTrabajadores[[#This Row],[Nombre Trabajador]],TablaOtrosPagos[[#All],[Importe]]))=0,0,SUMIF(TablaOtrosPagos[[#All],[Trabajador]],TablaTrabajadores[[#This Row],[Nombre Trabajador]],TablaOtrosPagos[[#All],[Importe]])),2) -> #REF! | Y7: =IF(OR(TablaOrganismo[Fecha Final de pago]="",TablaTrabajadores[[#This Row],[Fecha Inicio Relación Laboral]]=""),"",CONCATENATE("P",ROUNDDOWN((TablaOrganismo[Fecha Final de pago]-TablaTrabajadores[[#This Row],[Fecha Inicio Relación Laboral]])/7,0),"W")) -> P204W | Z7: =COUNTIF(TablaPercepciones[[#All],[Trabajador]],TablaTrabajadores[[#This Row],[Nombre Trabajador]]) -> 4 | AA7: =COUNTIF(TablaDeducciones[[#All],[Trabajador]],TablaTrabajadores[[#This Row],[Nombre Trabajador]]) -> 1 | AB7: =ROUND(IF((SUMIF(TablaPercepciones[[#All],[Trabajador]],TablaTrabajadores[[#This Row],[Nombre Trabajador]],TablaPercepciones[[#All],[Importe Gravado]]))=0,0,SUMIF(TablaPercepciones[[#All],[Trabajador]],TablaTrabajadores[[#This Row],[Nombre Trabajador]],TablaPercepciones[[#All],[Importe Gravado]])),2) -> #REF! | AC7: =ROUND(IF((SUMIF(TablaPercepciones[[#All],[Trabajador]],TablaTrabajadores[[#This Row],[Nombre Trabajador]],TablaPercepciones[[#All],[o]]))=0,0,SUMIF(TablaPercepciones[[#All],[Trabajador]],TablaTrabajadores[[#This Row],[Nombre Trabajador]],TablaPercepciones[[#All],[o]])),2) -> #REF! | AD7: =ROUND(IF(SUMIFS(TablaDeducciones[[#All],[Importe]],TablaDeducciones[[#All],[Trabajador]],TablaTrabajadores[[#This Row],[Nombre Trabajador]],TablaDeducciones[[#All],[Clave Deducción]],"<>002")=0,0,SUMIFS(TablaDeducciones[[#All],[Importe]],TablaDeducciones[[#All],[Trabajador]],TablaTrabajadores[[#This Row],[Nombre Trabajador]],TablaDeducciones[[#All],[Clave Deducción]],"<>002")),2) -> #REF! | AE7: =ROUND(IF((SUMIFS(TablaDeducciones[[#All],[Importe]],TablaDeducciones[[#All],[Trabajador]],TablaTrabajadores[[#This Row],[Nombre Trabajador]],TablaDeducciones[[#All],[Clave Deducción]],"=002"))=0,0,SUMIFS(TablaDeducciones[[#All],[Importe]],TablaDeducciones[[#All],[Trabajador]],TablaTrabajadores[[#This Row],[Nombre Trabajador]],TablaDeducciones[[#All],[Clave Deducción]],"=002")),2) -> 0 | AF7: =IF(TablaTrabajadores[[#This Row],[Origen del Recurso]]="","",VLOOKUP(TablaTrabajadores[[#This Row],[Origen del Recurso]],Cat!Y:Z,2,0)) -> IP | AG7: =IF(TablaTrabajadores[[#This Row],[Entidad Federativa]]="","",VLOOKUP(TablaTrabajadores[[#This Row],[Entidad Federativa]],Cat!AB:AC,2,0)) -> CHP | AH7: =COUNTIF(TablaHorasExtra[[#All],[Trabajador]],TablaTrabajadores[[#This Row],[Nombre Trabajador]]) -> 0 | AI7: =COUNTIF(TablaOtrosPagos[[#All],[Trabajador]],TablaTrabajadores[[#This Row],[Nombre Trabajador]]) -> 1 | AJ7: =IF(TablaTrabajadores[[#This Row],[Tipo de Jornada]]="","",VLOOKUP(TablaTrabajadores[[#This Row],[Tipo de Jornada]],Cat!AK:AL,2,0)) -> 1 | AK7: =ROUND(IFERROR(SUMIFS(TablaPercepciones[[#All],[Importe Gravado]],TablaPercepciones[[#All],[Trabajador]],TablaTrabajadores[[#This Row],[Nombre Trabajador]],TablaPercepciones[[#All],[Clave Percepción]],"<>022",TablaPercepciones[[#All],[Clave Percepción]],"<>023",TablaPercepciones[[#All],[Clave Percepción]],"<>025",TablaPercepciones[[#All],[Clave Percepción]],"<>044"),0)+IFERROR(SUMIFS(TablaPercepciones[[#All],[o]],TablaPercepciones[[#All],[Trabajador]],TablaTrabajadores[[#This Row],[Nombre Trabajador]],TablaPercepciones[[#All],[Clave Percepción]],"<>022",TablaPercepciones[[#All],[Clave Percepción]],"<>023",TablaPercepciones[[#All],[Clave Percepción]],"<>025",TablaPercepciones[[#All],[Clave Percepción]],"<>044"),0),2) -> 0 | AL7: =ROUND(IFERROR(SUMIFS(TablaPercepciones[[#All],[Importe Gravado]],TablaPercepciones[[#All],[Trabajador]],TablaTrabajadores[[#This Row],[Nombre Trabajador]],TablaPercepciones[[#All],[Clave Percepción]],"=022"),0)+IFERROR(SUMIFS(TablaPercepciones[[#All],[Importe Gravado]],TablaPercepciones[[#All],[Trabajador]],TablaTrabajadores[[#This Row],[Nombre Trabajador]],TablaPercepciones[[#All],[Clave Percepción]],"=023"),0)+IFERROR(SUMIFS(TablaPercepciones[[#All],[Importe Gravado]],TablaPercepciones[[#All],[Trabajador]],TablaTrabajadores[[#This Row],[Nombre Trabajador]],TablaPercepciones[[#All],[Clave Percepción]],"=025"),0)+IFERROR(SUMIFS(TablaPercepciones[[#All],[o]],TablaPercepciones[[#All],[Trabajador]],TablaTrabajadores[[#This Row],[Nombre Trabajador]],TablaPercepciones[[#All],[Clave Percepción]],"=022"),0)+IFERROR(SUMIFS(TablaPercepciones[[#All],[o]],TablaPercepciones[[#All],[Trabajador]],TablaTrabajadores[[#This Row],[Nombre Trabajador]],TablaPercepciones[[#All],[Clave Percepción]],"=023"),0)+IFERROR(SUMIFS(TablaPercepciones[[#All],[o]],TablaPercepciones[[#All],[Trabajador]],TablaTrabajadores[[#This Row],[Nombre Trabajador]],TablaPercepciones[[#All],[Clave Percepción]],"=025"),0),2) -> 0 | AM7: =ROUND(IFERROR(SUMIFS(TablaPercepciones[[#All],[Importe Gravado]],TablaPercepciones[[#All],[Trabajador]],TablaTrabajadores[[#This Row],[Nombre Trabajador]],TablaPercepciones[[#All],[Clave Percepción]],"=039"),0)+IFERROR(SUMIFS(TablaPercepciones[[#All],[Importe Gravado]],TablaPercepciones[[#All],[Trabajador]],TablaTrabajadores[[#This Row],[Nombre Trabajador]],TablaPercepciones[[#All],[Clave Percepción]],"=044"),0)+IFERROR(SUMIFS(TablaPercepciones[[#All],[o]],TablaPercepciones[[#All],[Trabajador]],TablaTrabajadores[[#This Row],[Nombre Trabajador]],TablaPercepciones[[#All],[Clave Percepción]],"=039"),0)+IFERROR(SUMIFS(TablaPercepciones[[#All],[o]],TablaPercepciones[[#All],[Trabajador]],TablaTrabajadores[[#This Row],[Nombre Trabajador]],TablaPercepciones[[#All],[Clave Percepción]],"=044"),0),2) -> 0 | AN7: Diurna
A8: 7 | B8: LOML860415SN4 | C8: LOPEZ MENDEZ LETICIA GUADALUPE | D8: LOML860415MCSPNT05 | E8: 71128617330 | F8: 43647 | G8: Contrato de trabajo por tiempo indeterminado | H8: Sueldos | I8: 5170 | J8: GERENCIA DE RADIO XHCTN LA TRINITARIA | K8: VELADOR | L8: 1 | M8: 157.26603 | N8: Ingresos propios | P8: Chiapas | Q8: joluma122@hotmail.com | R8: canal10humanos@gmail.com | T8: =IF(TablaTrabajadores[[#This Row],[Tipo de Contrato]]="","",VLOOKUP(TablaTrabajadores[[#This Row],[Tipo de Contrato]],Cat!$G$1:$H$12,2,0)) -> 1 | U8: =IF(TablaTrabajadores[[#This Row],[Tipo de Régimen]]="","",VLOOKUP(TablaTrabajadores[[#This Row],[Tipo de Régimen]],Cat!$J$1:$K$13,2,0)) -> 2 | V8: =ROUND(IF((SUMIF(TablaPercepciones[[#All],[Trabajador]],TablaTrabajadores[[#This Row],[Nombre Trabajador]],TablaPercepciones[[#All],[Importe Gravado]])+SUMIF(TablaPercepciones[[#All],[Trabajador]],TablaTrabajadores[[#This Row],[Nombre Trabajador]],TablaPercepciones[[#All],[o]]))=0,0,SUMIF(TablaPercepciones[[#All],[Trabajador]],TablaTrabajadores[[#This Row],[Nombre Trabajador]],TablaPercepciones[[#All],[Importe Gravado]])+SUMIF(TablaPercepciones[[#All],[Trabajador]],TablaTrabajadores[[#This Row],[Nombre Trabajador]],TablaPercepciones[[#All],[o]])),2) -> #REF! | W8: =ROUND(IF((SUMIF(TablaDeducciones[[#All],[Trabajador]],TablaTrabajadores[[#This Row],[Nombre Trabajador]],TablaDeducciones[[#All],[Importe]]))=0,0,SUMIF(TablaDeducciones[[#All],[Trabajador]],TablaTrabajadores[[#This Row],[Nombre Trabajador]],TablaDeducciones[[#All],[Importe]])),2) -> #REF! | X8: =ROUND(IF((SUMIF(TablaOtrosPagos[[#All],[Trabajador]],TablaTrabajadores[[#This Row],[Nombre Trabajador]],TablaOtrosPagos[[#All],[Importe]]))=0,0,SUMIF(TablaOtrosPagos[[#All],[Trabajador]],TablaTrabajadores[[#This Row],[Nombre Trabajador]],TablaOtrosPagos[[#All],[Importe]])),2) -> #REF! | Y8: =IF(OR(TablaOrganismo[Fecha Final de pago]="",TablaTrabajadores[[#This Row],[Fecha Inicio Relación Laboral]]=""),"",CONCATENATE("P",ROUNDDOWN((TablaOrganismo[Fecha Final de pago]-TablaTrabajadores[[#This Row],[Fecha Inicio Relación Laboral]])/7,0),"W")) -> P100W | Z8: =COUNTIF(TablaPercepciones[[#All],[Trabajador]],TablaTrabajadores[[#This Row],[Nombre Trabajador]]) -> 4 | AA8: =COUNTIF(TablaDeducciones[[#All],[Trabajador]],TablaTrabajadores[[#This Row],[Nombre Trabajador]]) -> 1 | AB8: =ROUND(IF((SUMIF(TablaPercepciones[[#All],[Trabajador]],TablaTrabajadores[[#This Row],[Nombre Trabajador]],TablaPercepciones[[#All],[Importe Gravado]]))=0,0,SUMIF(TablaPercepciones[[#All],[Trabajador]],TablaTrabajadores[[#This Row],[Nombre Trabajador]],TablaPercepciones[[#All],[Importe Gravado]])),2) -> #REF! | AC8: =ROUND(IF((SUMIF(TablaPercepciones[[#All],[Trabajador]],TablaTrabajadores[[#This Row],[Nombre Trabajador]],TablaPercepciones[[#All],[o]]))=0,0,SUMIF(TablaPercepciones[[#All],[Trabajador]],TablaTrabajadores[[#This Row],[Nombre Trabajador]],TablaPercepciones[[#All],[o]])),2) -> #REF! | AD8: =ROUND(IF(SUMIFS(TablaDeducciones[[#All],[Importe]],TablaDeducciones[[#All],[Trabajador]],TablaTrabajadores[[#This Row],[Nombre Trabajador]],TablaDeducciones[[#All],[Clave Deducción]],"<>002")=0,0,SUMIFS(TablaDeducciones[[#All],[Importe]],TablaDeducciones[[#All],[Trabajador]],TablaTrabajadores[[#This Row],[Nombre Trabajador]],TablaDeducciones[[#All],[Clave Deducción]],"<>002")),2) -> #REF! | AE8: =ROUND(IF((SUMIFS(TablaDeducciones[[#All],[Importe]],TablaDeducciones[[#All],[Trabajador]],TablaTrabajadores[[#This Row],[Nombre Trabajador]],TablaDeducciones[[#All],[Clave Deducción]],"=002"))=0,0,SUMIFS(TablaDeducciones[[#All],[Importe]],TablaDeducciones[[#All],[Trabajador]],TablaTrabajadores[[#This Row],[Nombre Trabajador]],TablaDeducciones[[#All],[Clave Deducción]],"=002")),2) -> 0 | AF8: =IF(TablaTrabajadores[[#This Row],[Origen del Recurso]]="","",VLOOKUP(TablaTrabajadores[[#This Row],[Origen del Recurso]],Cat!Y:Z,2,0)) -> IP | AG8: =IF(TablaTrabajadores[[#This Row],[Entidad Federativa]]="","",VLOOKUP(TablaTrabajadores[[#This Row],[Entidad Federativa]],Cat!AB:AC,2,0)) -> CHP | AH8: =COUNTIF(TablaHorasExtra[[#All],[Trabajador]],TablaTrabajadores[[#This Row],[Nombre Trabajador]]) -> 0 | AI8: =COUNTIF(TablaOtrosPagos[[#All],[Trabajador]],TablaTrabajadores[[#This Row],[Nombre Trabajador]]) -> 1 | AJ8: =IF(TablaTrabajadores[[#This Row],[Tipo de Jornada]]="","",VLOOKUP(TablaTrabajadores[[#This Row],[Tipo de Jornada]],Cat!AK:AL,2,0)) -> 3 | AK8: =ROUND(IFERROR(SUMIFS(TablaPercepciones[[#All],[Importe Gravado]],TablaPercepciones[[#All],[Trabajador]],TablaTrabajadores[[#This Row],[Nombre Trabajador]],TablaPercepciones[[#All],[Clave Percepción]],"<>022",TablaPercepciones[[#All],[Clave Percepción]],"<>023",TablaPercepciones[[#All],[Clave Percepción]],"<>025",TablaPercepciones[[#All],[Clave Percepción]],"<>044"),0)+IFERROR(SUMIFS(TablaPercepciones[[#All],[o]],TablaPercepciones[[#All],[Trabajador]],TablaTrabajadores[[#This Row],[Nombre Trabajador]],TablaPercepciones[[#All],[Clave Percepción]],"<>022",TablaPercepciones[[#All],[Clave Percepción]],"<>023",TablaPercepciones[[#All],[Clave Percepción]],"<>025",TablaPercepciones[[#All],[Clave Percepción]],"<>044"),0),2) -> 0 | AL8: =ROUND(IFERROR(SUMIFS(TablaPercepciones[[#All],[Importe Gravado]],TablaPercepciones[[#All],[Trabajador]],TablaTrabajadores[[#This Row],[Nombre Trabajador]],TablaPercepciones[[#All],[Clave Percepción]],"=022"),0)+IFERROR(SUMIFS(TablaPercepciones[[#All],[Importe Gravado]],TablaPercepciones[[#All],[Trabajador]],TablaTrabajadores[[#This Row],[Nombre Trabajador]],TablaPercepciones[[#All],[Clave Percepción]],"=023"),0)+IFERROR(SUMIFS(TablaPercepciones[[#All],[Importe Gravado]],TablaPercepciones[[#All],[Trabajador]],TablaTrabajadores[[#This Row],[Nombre Trabajador]],TablaPercepciones[[#All],[Clave Percepción]],"=025"),0)+IFERROR(SUMIFS(TablaPercepciones[[#All],[o]],TablaPercepciones[[#All],[Trabajador]],TablaTrabajadores[[#This Row],[Nombre Trabajador]],TablaPercepciones[[#All],[Clave Percepción]],"=022"),0)+IFERROR(SUMIFS(TablaPercepciones[[#All],[o]],TablaPercepciones[[#All],[Trabajador]],TablaTrabajadores[[#This Row],[Nombre Trabajador]],TablaPercepciones[[#All],[Clave Percepción]],"=023"),0)+IFERROR(SUMIFS(TablaPercepciones[[#All],[o]],TablaPercepciones[[#All],[Trabajador]],TablaTrabajadores[[#This Row],[Nombre Trabajador]],TablaPercepciones[[#All],[Clave Percepción]],"=025"),0),2) -> 0 | AM8: =ROUND(IFERROR(SUMIFS(TablaPercepciones[[#All],[Importe Gravado]],TablaPercepciones[[#All],[Trabajador]],TablaTrabajadores[[#This Row],[Nombre Trabajador]],TablaPercepciones[[#All],[Clave Percepción]],"=039"),0)+IFERROR(SUMIFS(TablaPercepciones[[#All],[Importe Gravado]],TablaPercepciones[[#All],[Trabajador]],TablaTrabajadores[[#This Row],[Nombre Trabajador]],TablaPercepciones[[#All],[Clave Percepción]],"=044"),0)+IFERROR(SUMIFS(TablaPercepciones[[#All],[o]],TablaPercepciones[[#All],[Trabajador]],TablaTrabajadores[[#This Row],[Nombre Trabajador]],TablaPercepciones[[#All],[Clave Percepción]],"=039"),0)+IFERROR(SUMIFS(TablaPercepciones[[#All],[o]],TablaPercepciones[[#All],[Trabajador]],TablaTrabajadores[[#This Row],[Nombre Trabajador]],TablaPercepciones[[#All],[Clave Percepción]],"=044"),0),2) -> 0 | AN8: Mixta
A9: 8 | B9: LOOL710327L22 | C9: LOPEZ OVANDO LEANDRA GUADALUPE | D9: LOOL710327MCSPVN04 | E9: 71917147556 | F9: 43116 | G9: Contrato de trabajo por tiempo indeterminado | H9: Sueldos | I9: 5126 | J9: OFICINA DE PRODUCCION | K9: CONDUCTOR A | L9: 1 | M9: 166.5397 | N9: Ingresos propios | P9: Chiapas | Q9: grupera29103@hotmail.com | R9: canal10humanos@gmail.com | T9: =IF(TablaTrabajadores[[#This Row],[Tipo de Contrato]]="","",VLOOKUP(TablaTrabajadores[[#This Row],[Tipo de Contrato]],Cat!$G$1:$H$12,2,0)) -> 1 | U9: =IF(TablaTrabajadores[[#This Row],[Tipo de Régimen]]="","",VLOOKUP(TablaTrabajadores[[#This Row],[Tipo de Régimen]],Cat!$J$1:$K$13,2,0)) -> 2 | V9: =ROUND(IF((SUMIF(TablaPercepciones[[#All],[Trabajador]],TablaTrabajadores[[#This Row],[Nombre Trabajador]],TablaPercepciones[[#All],[Importe Gravado]])+SUMIF(TablaPercepciones[[#All],[Trabajador]],TablaTrabajadores[[#This Row],[Nombre Trabajador]],TablaPercepciones[[#All],[o]]))=0,0,SUMIF(TablaPercepciones[[#All],[Trabajador]],TablaTrabajadores[[#This Row],[Nombre Trabajador]],TablaPercepciones[[#All],[Importe Gravado]])+SUMIF(TablaPercepciones[[#All],[Trabajador]],TablaTrabajadores[[#This Row],[Nombre Trabajador]],TablaPercepciones[[#All],[o]])),2) -> #REF! | W9: =ROUND(IF((SUMIF(TablaDeducciones[[#All],[Trabajador]],TablaTrabajadores[[#This Row],[Nombre Trabajador]],TablaDeducciones[[#All],[Importe]]))=0,0,SUMIF(TablaDeducciones[[#All],[Trabajador]],TablaTrabajadores[[#This Row],[Nombre Trabajador]],TablaDeducciones[[#All],[Importe]])),2) -> #REF! | X9: =ROUND(IF((SUMIF(TablaOtrosPagos[[#All],[Trabajador]],TablaTrabajadores[[#This Row],[Nombre Trabajador]],TablaOtrosPagos[[#All],[Importe]]))=0,0,SUMIF(TablaOtrosPagos[[#All],[Trabajador]],TablaTrabajadores[[#This Row],[Nombre Trabajador]],TablaOtrosPagos[[#All],[Importe]])),2) -> #REF! | Y9: =IF(OR(TablaOrganismo[Fecha Final de pago]="",TablaTrabajadores[[#This Row],[Fecha Inicio Relación Laboral]]=""),"",CONCATENATE("P",ROUNDDOWN((TablaOrganismo[Fecha Final de pago]-TablaTrabajadores[[#This Row],[Fecha Inicio Relación Laboral]])/7,0),"W")) -> P175W | Z9: =COUNTIF(TablaPercepciones[[#All],[Trabajador]],TablaTrabajadores[[#This Row],[Nombre Trabajador]]) -> 4 | AA9: =COUNTIF(TablaDeducciones[[#All],[Trabajador]],TablaTrabajadores[[#This Row],[Nombre Trabajador]]) -> 3 | AB9: =ROUND(IF((SUMIF(TablaPercepciones[[#All],[Trabajador]],TablaTrabajadores[[#This Row],[Nombre Trabajador]],TablaPercepciones[[#All],[Importe Gravado]]))=0,0,SUMIF(TablaPercepciones[[#All],[Trabajador]],TablaTrabajadores[[#This Row],[Nombre Trabajador]],TablaPercepciones[[#All],[Importe Gravado]])),2) -> #REF! | AC9: =ROUND(IF((SUMIF(TablaPercepciones[[#All],[Trabajador]],TablaTrabajadores[[#This Row],[Nombre Trabajador]],TablaPercepciones[[#All],[o]]))=0,0,SUMIF(TablaPercepciones[[#All],[Trabajador]],TablaTrabajadores[[#This Row],[Nombre Trabajador]],TablaPercepciones[[#All],[o]])),2) -> #REF! | AD9: =ROUND(IF(SUMIFS(TablaDeducciones[[#All],[Importe]],TablaDeducciones[[#All],[Trabajador]],TablaTrabajadores[[#This Row],[Nombre Trabajador]],TablaDeducciones[[#All],[Clave Deducción]],"<>002")=0,0,SUMIFS(TablaDeducciones[[#All],[Importe]],TablaDeducciones[[#All],[Trabajador]],TablaTrabajadores[[#This Row],[Nombre Trabajador]],TablaDeducciones[[#All],[Clave Deducción]],"<>002")),2) -> #REF! | AE9: =ROUND(IF((SUMIFS(TablaDeducciones[[#All],[Importe]],TablaDeducciones[[#All],[Trabajador]],TablaTrabajadores[[#This Row],[Nombre Trabajador]],TablaDeducciones[[#All],[Clave Deducción]],"=002"))=0,0,SUMIFS(TablaDeducciones[[#All],[Importe]],TablaDeducciones[[#All],[Trabajador]],TablaTrabajadores[[#This Row],[Nombre Trabajador]],TablaDeducciones[[#All],[Clave Deducción]],"=002")),2) -> 0 | AF9: =IF(TablaTrabajadores[[#This Row],[Origen del Recurso]]="","",VLOOKUP(TablaTrabajadores[[#This Row],[Origen del Recurso]],Cat!Y:Z,2,0)) -> IP | AG9: =IF(TablaTrabajadores[[#This Row],[Entidad Federativa]]="","",VLOOKUP(TablaTrabajadores[[#This Row],[Entidad Federativa]],Cat!AB:AC,2,0)) -> CHP | AH9: =COUNTIF(TablaHorasExtra[[#All],[Trabajador]],TablaTrabajadores[[#This Row],[Nombre Trabajador]]) -> 0 | AI9: =COUNTIF(TablaOtrosPagos[[#All],[Trabajador]],TablaTrabajadores[[#This Row],[Nombre Trabajador]]) -> 1 | AJ9: =IF(TablaTrabajadores[[#This Row],[Tipo de Jornada]]="","",VLOOKUP(TablaTrabajadores[[#This Row],[Tipo de Jornada]],Cat!AK:AL,2,0)) -> 1 | AK9: =ROUND(IFERROR(SUMIFS(TablaPercepciones[[#All],[Importe Gravado]],TablaPercepciones[[#All],[Trabajador]],TablaTrabajadores[[#This Row],[Nombre Trabajador]],TablaPercepciones[[#All],[Clave Percepción]],"<>022",TablaPercepciones[[#All],[Clave Percepción]],"<>023",TablaPercepciones[[#All],[Clave Percepción]],"<>025",TablaPercepciones[[#All],[Clave Percepción]],"<>044"),0)+IFERROR(SUMIFS(TablaPercepciones[[#All],[o]],TablaPercepciones[[#All],[Trabajador]],TablaTrabajadores[[#This Row],[Nombre Trabajador]],TablaPercepciones[[#All],[Clave Percepción]],"<>022",TablaPercepciones[[#All],[Clave Percepción]],"<>023",TablaPercepciones[[#All],[Clave Percepción]],"<>025",TablaPercepciones[[#All],[Clave Percepción]],"<>044"),0),2) -> 0 | AL9: =ROUND(IFERROR(SUMIFS(TablaPercepciones[[#All],[Importe Gravado]],TablaPercepciones[[#All],[Trabajador]],TablaTrabajadores[[#This Row],[Nombre Trabajador]],TablaPercepciones[[#All],[Clave Percepción]],"=022"),0)+IFERROR(SUMIFS(TablaPercepciones[[#All],[Importe Gravado]],TablaPercepciones[[#All],[Trabajador]],TablaTrabajadores[[#This Row],[Nombre Trabajador]],TablaPercepciones[[#All],[Clave Percepción]],"=023"),0)+IFERROR(SUMIFS(TablaPercepciones[[#All],[Importe Gravado]],TablaPercepciones[[#All],[Trabajador]],TablaTrabajadores[[#This Row],[Nombre Trabajador]],TablaPercepciones[[#All],[Clave Percepción]],"=025"),0)+IFERROR(SUMIFS(TablaPercepciones[[#All],[o]],TablaPercepciones[[#All],[Trabajador]],TablaTrabajadores[[#This Row],[Nombre Trabajador]],TablaPercepciones[[#All],[Clave Percepción]],"=022"),0)+IFERROR(SUMIFS(TablaPercepciones[[#All],[o]],TablaPercepciones[[#All],[Trabajador]],TablaTrabajadores[[#This Row],[Nombre Trabajador]],TablaPercepciones[[#All],[Clave Percepción]],"=023"),0)+IFERROR(SUMIFS(TablaPercepciones[[#All],[o]],TablaPercepciones[[#All],[Trabajador]],TablaTrabajadores[[#This Row],[Nombre Trabajador]],TablaPercepciones[[#All],[Clave Percepción]],"=025"),0),2) -> 0 | AM9: =ROUND(IFERROR(SUMIFS(TablaPercepciones[[#All],[Importe Gravado]],TablaPercepciones[[#All],[Trabajador]],TablaTrabajadores[[#This Row],[Nombre Trabajador]],TablaPercepciones[[#All],[Clave Percepción]],"=039"),0)+IFERROR(SUMIFS(TablaPercepciones[[#All],[Importe Gravado]],TablaPercepciones[[#All],[Trabajador]],TablaTrabajadores[[#This Row],[Nombre Trabajador]],TablaPercepciones[[#All],[Clave Percepción]],"=044"),0)+IFERROR(SUMIFS(TablaPercepciones[[#All],[o]],TablaPercepciones[[#All],[Trabajador]],TablaTrabajadores[[#This Row],[Nombre Trabajador]],TablaPercepciones[[#All],[Clave Percepción]],"=039"),0)+IFERROR(SUMIFS(TablaPercepciones[[#All],[o]],TablaPercepciones[[#All],[Trabajador]],TablaTrabajadores[[#This Row],[Nombre Trabajador]],TablaPercepciones[[#All],[Clave Percepción]],"=044"),0),2) -> 0 | AN9: Diurna
